Workbook

Sheet DCF
B1: DCF valuation model - GENTEX - by Michael (Minh) Thai
B3: Ticker | C3: GNTX | E3: Implied Share Price | H3: =N119 -> 3.528661 | K3: Please choose the scenario from the "colored box" below
B4: Date | C4: 45799 | E4: Current Share Price | H4: 23.4 | J4: Scenario: | K4: Conservative | L4: {=_xlfn.IFS(K4="Conservative", 1, K4="Bear", 2, K4="Optimistic", 3, TRUE, 1)} -> 1
B5: Year-End | C5: 46022 | E5: Implied Upside / (Downside) | H5: =H3/H4-1 -> -0.84920252
A7: x | B7: Assumptions
B9: Switches | G9: Conservative | M9: Base | S9: Optimistic
B10: Revenue | G10: Revenue | J10: Year | K10: Metric | M10: Revenue | P10: Year | Q10: Metric | S10: Revenue | V10: Year | W10: Metric
B12: Insurance and Other | E12: =$L$4 -> 1 | G12: Revenue | J12: 2026 | K12: -0.073 | M12: Revenue | P12: 2026 | Q12: 0.046 | S12: Revenue | V12: 2026 | W12: 0.065
G13: Revenue | J13: 2030 | K13: 0.02 | M13: Revenue | P13: 2030 | Q13: 0.035 | S13: Revenue | V13: 2030 | W13: 0.065
B15: Costs & OpEx | G15: Costs & OpEx | J15: Year | K15: Metric | M15: Costs & OpEx | P15: Year | Q15: Metric | S15: Costs & OpEx | V15: Year | W15: Metric
B16: COGS | E16: =$L$4 -> 1 | G16: COGS | J16: 2026 | K16: 0.685 | M16: COGS | P16: 2026 | Q16: 0.655 | S16: COGS | V16: 2026 | W16: 0.65
B17: R&D Ex | E17: =$L$4 -> 1 | G17: COGS | J17: 2030 | K17: 0.68 | M17: COGS | P17: 2030 | Q17: 0.645 | S17: COGS | V17: 2030 | W17: 0.64
B18: SG&A | E18: =$L$4 -> 1 | G18: R&D Ex | J18: 2026 | K18: 0.086 | M18: R&D Ex | P18: 2026 | Q18: 0.08 | S18: R&D Ex | V18: 2026 | W18: 0.078
G19: R&D Ex | J19: 2030 | K19: 0.09 | M19: R&D Ex | P19: 2030 | Q19: 0.08 | S19: R&D Ex | V19: 2030 | W19: 0.075
G20: SG&A | J20: 2026 | K20: 0.084 | M20: SG&A | P20: 2026 | Q20: 0.076 | S20: SG&A | V20: 2026 | W20: 0.074
G21: SG&A | J21: 2030 | K21: 0.075 | M21: SG&A | P21: 2030 | Q21: 0.065 | S21: SG&A | V21: 2030 | W21: 0.055
B23: Valuation | G23: Valuation | K23: Metric | M23: Valuation | Q23: Metric | S23: Valuation | W23: Metric
B24: WACC | E24: =$L$4 -> 1 | G24: WACC | K24: 0.105 | M24: WACC | Q24: 0.095 | S24: WACC | W24: 0.085
B25: TGR | E25: =$L$4 -> 1 | G25: TGR | K25: 0.02 | M25: TGR | Q25: 0.03 | S25: TGR | W25: 0.04
B27: Other Assumptions
B28: Taxes | E28: 0.21
B29: D&A | E29: =AVERAGE(G76:I76) -> 0.040861849
B30: CapEx | E30: =AVERAGE(G79:I79) -> 0.064454107
B31: Change in NWC | E31: =AVERAGE(F82:I82) -> 0.012186713
B32: WACC | E32: =CHOOSE(E24,K24,Q24,W24) -> 0.105
B33: TGR | E33: =CHOOSE(E25,K25,Q25,W25) -> 0.02
A35: x | B35: Revenue Build | E35: 2021 | F35: =E35+1 -> 2022 | G35: =F35+1 -> 2023 | H35: =G35+1 -> 2024 | I35: =H35+1 -> 2025 | J35: =I35+1 -> 2026 | K35: =J35+1 -> 2027 | L35: =K35+1 -> 2028 | M35: =L35+1 -> 2029 | N35: =M35+1 -> 2030
B36: Revenue | E36: ='Income - As Reported'!C9 -> 1731.1699 | F36: ='Income - As Reported'!D9 -> 1918.958 | G36: ='Income - As Reported'!E9 -> 2299.215 | H36: ='Income - As Reported'!F9 -> 2313.3143 | I36: ='Income - As Reported'!G9 -> 2534.269 | J36: =I36*(1+J37) -> 2642.3353 | K36: =J36*(1+K37) -> 2747.7433 | L36: =K36*(1+L37) -> 2849.8 | M36: =L36*(1+M37) -> 2947.8103 | N36: =M36*(1+N37) -> 3006.7666
B37: % growth | E37: -- | F37: =F36/E36-1 -> 0.10847468 | G37: =G36/F36-1 -> 0.19815806 | H37: =H36/G36-1 -> 0.0061322234 | I37: =I36/H36-1 -> 0.095514345 | J37: =OFFSET(J37,$E$12,0) -> 0.042642 | K37: =OFFSET(K37,$E$12,0) -> 0.039892 | L37: =OFFSET(L37,$E$12,0) -> 0.037142 | M37: =OFFSET(M37,$E$12,0) -> 0.034392 | N37: =OFFSET(N37,$E$12,0) -> 0.02
B38: Conservative | J38: =J39*(1+K12) -> 0.042642 | K38: =J38-(($J$39-$N$39)/($N$35-$J$35)) -> 0.039892 | L38: =K38-(($J$39-$N$39)/($N$35-$J$35)) -> 0.037142 | M38: =L38-(($J$39-$N$39)/($N$35-$J$35)) -> 0.034392 | N38: =K13 -> 0.02
B39: Base | J39: =Q12 -> 0.046 | K39: =J39-(($J$39-$N$39)/($N$35-$J$35)) -> 0.04325 | L39: =K39-(($J$39-$N$39)/($N$35-$J$35)) -> 0.0405 | M39: =L39-(($J$39-$N$39)/($N$35-$J$35)) -> 0.03775 | N39: =Q13 -> 0.035
B40: Optimistic | J40: =J39*(1+W12) -> 0.04899 | K40: =J40-(($J$39-$N$39)/($N$35-$J$35)) -> 0.04624 | L40: =K40-(($J$39-$N$39)/($N$35-$J$35)) -> 0.04349 | M40: =L40-(($J$39-$N$39)/($N$35-$J$35)) -> 0.04074 | N40: =W13 -> 0.065
B43: Costs & OpEx Build | E43: 2021 | F43: =E43+1 -> 2022 | G43: =F43+1 -> 2023 | H43: =G43+1 -> 2024 | I43: =H43+1 -> 2025 | J43: =I43+1 -> 2026 | K43: =J43+1 -> 2027 | L43: =K43+1 -> 2028 | M43: =L43+1 -> 2029 | N43: =M43+1 -> 2030
B44: COGS | E44: ='Income - As Reported'!C12 -> 1111.4621 | F44: ='Income - As Reported'!D12 -> 1309.1439 | G44: ='Income - As Reported'!E12 -> 1536.585 | H44: ='Income - As Reported'!F12 -> 1542.2241 | I44: ='Income - As Reported'!G12 -> 1667.56 | J44: =J45*J$36 -> 2916.2794 | K44: =K45*K$36 -> 2741.5781 | L44: =L45*L$36 -> 2541.5585 | M44: =M45*M$36 -> 2316.7394 | N44: =N45*N$36 -> 2044.6013
B45: % margin | E45: =E44/E$36 -> 0.64202947 | F45: =F44/F$36 -> 0.68221603 | G45: =G44/G$36 -> 0.66830853 | H45: =H44/H$36 -> 0.66667296 | I45: =I44/I$36 -> 0.65800434 | J45: =OFFSET(J45,$E$16,0) -> 1.103675 | K45: =OFFSET(K45,$E$16,0) -> 0.99775625 | L45: =OFFSET(L45,$E$16,0) -> 0.8918375 | M45: =OFFSET(M45,$E$16,0) -> 0.78591875 | N45: =OFFSET(N45,$E$16,0) -> 0.68
B46: Conservative | J46: =J47*(1+K16) -> 1.103675 | K46: =J46-(($J$46-$N$46)/($N$43-$J$43)) -> 0.99775625 | L46: =K46-(($J$46-$N$46)/($N$43-$J$43)) -> 0.8918375 | M46: =L46-(($J$46-$N$46)/($N$43-$J$43)) -> 0.78591875 | N46: =K17 -> 0.68
B47: Base | J47: =Q16 -> 0.655 | K47: =J47-(($J$47-$N$47)/($N$43-$J$43)) -> 0.6525 | L47: =K47-(($J$47-$N$47)/($N$43-$J$43)) -> 0.65 | M47: =L47-(($J$47-$N$47)/($N$43-$J$43)) -> 0.6475 | N47: =Q17 -> 0.645
B48: Optimistic | J48: =J47*(1+W16) -> 1.08075 | K48: =J48-(($J$48-$N$48)/($N$43-$J$43)) -> 0.9705625 | L48: =K48-(($J$48-$N$48)/($N$43-$J$43)) -> 0.860375 | M48: =L48-(($J$48-$N$48)/($N$43-$J$43)) -> 0.7501875 | N48: =W17 -> 0.64
B50: R&D Ex | E50: ='Income - As Reported'!C13 -> 117.7637 | F50: ='Income - As Reported'!D13 -> 133.3088 | G50: ='Income - As Reported'!E13 -> 154.3597 | H50: ='Income - As Reported'!F13 -> 181.4752 | I50: ='Income - As Reported'!G13 -> 203.2598 | J50: =J51*J$36 -> 229.56609 | K50: =K51*K$36 -> 240.86718 | L50: =L51*L$36 -> 252.03631 | M50: =M51*M$36 -> 263.00364 | N50: =N51*N$36 -> 270.60899
B51: % margin | E51: =E50/E$36 -> 0.068025501 | F51: =F50/F$36 -> 0.069469368 | G51: =G50/G$36 -> 0.067135827 | H51: =H50/H$36 -> 0.078448138 | I51: =I50/I$36 -> 0.080204509 | J51: =OFFSET(J51,$E$17,0) -> 0.08688 | K51: =OFFSET(K51,$E$17,0) -> 0.08766 | L51: =OFFSET(L51,$E$17,0) -> 0.08844 | M51: =OFFSET(M51,$E$17,0) -> 0.08922 | N51: =OFFSET(N51,$E$17,0) -> 0.09
...

Sheet Income - As Reported
A2: Gentex Corp (GNTX US) - As Reported
A4: In Millions of USD except Per Share | C4: FY 2021 | D4: FY 2022 | E4: FY 2023 | F4: FY 2024 | G4: FY 2025
A5: 12 Months Ending | C5: 12/31/2021 | D5: 12/31/2022 | E5: 12/31/2023 | F5: 12/31/2024 | G5: 12/31/2025
A6: Income Statement
A7: Revenues
A8: Revenues | B8: ARD_REVENUES | C8: 1731.1699 | D8: 1918.958 | E8: 2299.215 | F8: 2313.3143 | G8: 2534.269
A9: Total Revenue | B9: ARD_TOTAL_REVENUES | C9: 1731.1699 | D9: 1918.958 | E9: 2299.215 | F9: 2313.3143 | G9: 2534.269
A10: Operating Expenses
A11: Total Operating Expenses | B11: ARD_TOTAL_OPERATING_EXPENSES | C11: 209.9259 | D11: 239.8081 | E11: 266.899 | F11: 311.3636 | G11: 392.7732
A12: Cost of Goods Sold | B12: ARD_COST_OF_GOODS_SOLD | C12: 1111.4621 | D12: 1309.1439 | E12: 1536.585 | F12: 1542.2241 | G12: 1667.56
A13: R & D Expenditures | B13: ARD_R&D_EXPENDITURES | C13: 117.7637 | D13: 133.3088 | E13: 154.3597 | F13: 181.4752 | G13: 203.2598
A14: Selling General and Administrative Expenses | B14: ARD_SELLING_GENERAL_ADMIN_EXP | C14: 92.1622 | D14: 106.4993 | E14: 112.5393 | F14: 121.0237 | G14: 177.8687
A15: Other Operating Expenses | B15: ARD_OTHER_OPERATING_EXPENSES | C15: — | D15: — | E15: — | F15: — | G15: 11.6447
A16: Write-Down/Impairment of Assets | B16: ARD_WRITEDOWN_IMPAIR_OF_ASSETS | C16: — | D16: — | E16: — | F16: 8.8647 | G16: 0
A17: Gross Profit | B17: ARD_GROSS_PROFITS | C17: 619.7078 | D17: 609.8142 | E17: 762.63 | F17: 771.0902 | G17: 866.7089
A18: Operating Income | B18: ARD_OPERATING_INCOME | C18: 409.782 | D18: 370.0061 | E18: 495.7311 | F18: 459.7266 | G18: 473.9358
A19: Non-Operating Expenses
A20: Income Tax Expense (Benefit) | B20: ARD_INCOME_TAX_EXP_BENEFIT | C20: 55.5545 | D20: 50.9657 | E20: 76.5779 | F20: 67.7259 | G20: 76.3803
A21: Investment Income | B21: ARD_INVESTMENT_INCOME | C21: -3.5898 | D21: -4.7958 | E21: -13.4984 | F21: -13.4028 | G21: 1.2893
A22: Income Before Income Taxes | B22: ARD_INCOME_BEFORE_INCOME_TAXES | C22: 416.3517 | D22: 369.7231 | E22: 504.9812 | F22: 472.2137 | G22: 461.0624
A23: Other Non-Operating (Income)/Expense - Net | B23: ARD_OTH_NON_OPER_INC_EXP_NET | C23: -2.98 | D23: 5.0789 | E23: 4.2482 | F23: 0.9157 | G23: 11.5841
A24: Earnings
A25: Minority/Non Controlling Interest | B25: ARD_MINORITY_NONCONTROL_INTEREST | C25: — | D25: — | E25: — | F25: — | G25: -0.1593
A26: Dividends Per Share | B26: ARD_DVD_PER_SH | C26: 0.48 | D26: 0.48 | E26: 0.48 | F26: 0.48 | G26: 0.48
A27: Basic EPS | B27: ARD_BASIC_EPS | C27: 1.51 | D27: 1.36 | E27: 1.84 | F27: 1.77 | G27: —
A28: Weighted Avg. Shares - Basic | B28: ARD_WEIGHTED_AVG_SHARES_BASIC | C28: — | D28: — | E28: — | F28: — | G28: —
A29: Diluted EPS | B29: ARD_DILUTED_EPS | C29: 1.5 | D29: 1.36 | E29: 1.84 | F29: 1.76 | G29: —
A30: Weighted Avg. Shares - Diluted | B30: ARD_WEIGHTED_AVG_SHARE_DILUTED | C30: — | D30: — | E30: — | F30: — | G30: —
A31: Net Income Available For Common Shareholders | B31: ARD_NET_INC_AVAIL_COM_SHRHLDR | C31: 360.7972 | D31: 318.7574 | E31: 428.4033 | F31: 404.4877 | G31: 384.8414
A32: Profit After Taxation Before Minority | B32: ARD_PROF_AFTER_TAX_BEF_MINORITY | C32: 360.7972 | D32: 318.7574 | E32: 428.4033 | F32: 404.4877 | G32: 384.6821
A33: Cumulative Net Income | B33: ARD_CUMULATIVE_NET_INCOME | C33: 360.7972 | D33: 318.7574 | E33: 428.4033 | F33: 404.4877 | G33: 384.8414
A34: Net Income | B34: ARD_NET_INC | C34: 360.7972 | D34: 318.7574 | E34: 428.4033 | F34: 404.4877 | G34: 384.8414
A35: Comprehensive Income
A36: Foreign Currency Translation Adjustments | B36: ARD_FOR_CRNCY_TRANSLATION_ADJ | C36: — | D36: -4.9528 | E36: -0.5025 | F36: -1.283 | G36: 5.5074
A37: Unrealized Gain (Loss) On Securities | B37: ARD_UNREALIZED_GL_ON_SECS | C37: — | D37: -14.0726 | E37: 10.2383 | F37: 1.8111 | G37: 2.454
A38: Income Tax Exp Related to Comprehensive Income | B38: ARD_INC_TAX_RELATE_TO_COMP_INC | C38: — | D38: 2.9552 | E38: -2.1501 | F38: -0.3803 | G38: -0.3109
A39: Other Comprehensive Income | B39: ARD_OTHER_COMPREHENSIVE_INCOME | C39: — | D39: — | E39: — | F39: — | G39: -0.9734
A40: Total Comprehensive Income | B40: ARD_TOTAL_COMPREHENSIVE_INCOME | C40: — | D40: 302.6872 | E40: 435.9891 | F40: 404.6355 | G40: 391.5185
A41: Net Income - Comprehensive Income | B41: ARD_COMPREHENSIVE_INCOME_NET_INC | C41: — | D41: 318.7574 | E41: 428.4033 | F41: 404.4877 | G41: 384.6821
A42: Net Income - Comprehensive Income | B42: ARDR_COMPR_INCOME_NET_INC | C42: 360.7972 | D42: 318.7574 | E42: 428.4033 | F42: 404.4877 | G42: 384.6821
...

Sheet Cash Flow - As Reported
A2: Gentex Corp (GNTX US) - As Reported
A4: In Millions of USD except Per Share | C4: FY 2021 | D4: FY 2022 | E4: FY 2023 | F4: FY 2024 | G4: FY 2025
A5: 12 Months Ending | C5: 12/31/2021 | D5: 12/31/2022 | E5: 12/31/2023 | F5: 12/31/2024 | G5: 12/31/2025
A6: Cash Flow
A7: Cash From Operating Activities
A8: Net Income - CF | B8: ARD_NET_INCOME_CF | C8: 360.7972 | D8: 318.7574 | E8: 428.4033 | F8: 404.4877 | G8: 384.6821
A9: Depreciation And Amortization - CF | B9: ARD_DEPRECIATION_AND_AMORT_CF | C9: 99.112 | D9: 96.5684 | E9: 93.3212 | F9: 94.7147 | G9: 104.0418
A10: Deferred Income Taxes - CF | B10: ARD_DEFERRED_INCOME_TAXES_CF | C10: -41.6948 | D10: -17.7778 | E10: -17.7351 | F10: -12.4214 | G10: -18.4062
A11: Disposal/Sale of Assets | B11: ARD_DISPOSAL_SALE_OF_ASSETS | C11: -0.2578 | D11: -0.0423 | E11: 0.0878 | F11: -1.2047 | G11: -2.8881
A12: Stock Based Compensation | B12: ARD_STOCK_BASED_COMPENSATION | C12: 27.4216 | D12: 30.2286 | E12: 39.1974 | F12: 39.5394 | G12: 36.6498
A13: Change in Inventories | B13: ARD_CHANGE_IN_INVENTORIES | C13: -89.9756 | D13: -88.0928 | E13: 2.1272 | F13: -32.6244 | G13: 18.1383
A14: Change in Accounts Payable | B14: ARD_CHANGE_IN_ACCOUNTS_PAYABLE | C14: 7.2663 | D14: 37.4235 | E14: 40.9515 | F14: -26.0212 | G14: 52.4026
A15: Change in Accounts Receivable | B15: ARD_CHG_IN_ACCOUNTS_RECEIVABLE | C15: 35.1354 | D15: -26.6988 | E15: -45.2511 | F15: 27.1067 | G15: -14.6155
A16: Change in Prepaid Expenses | B16: ARD_CHANGE_IN_PREPAID_EXP | C16: -20.242 | D16: -28.7883 | E16: -4.1019 | F16: -9.8736 | G16: 0.2146
A17: Change in Accrued Expenses | B17: ARD_CHANGE_IN_ACCRUED_EXP | C17: -14.3229 | D17: 14.9099 | E17: -5.7354 | F17: 1.0196 | G17: -1.6846
A18: Impairments | B18: ARD_IMPAIRMENTS | C18: — | D18: — | E18: — | F18: 8.8647 | G18: 14.082
A19: Total Cash Flows From Operations | B19: ARD_TOT_CASH_FLOWS_FROM_OPS | C19: 362.1676 | D19: 338.2005 | E19: 537.2496 | F19: 498.2132 | G19: 587.1263
A20: Gain (Loss) On Sale of Investments and Mkt Sec | B20: ARD_GL_ON_SALE_OF_INV_MKT_SEC | C20: -1.072 | D20: 1.7129 | E20: 5.9847 | F20: 4.6257 | G20: 14.5096
A21: Cash From Investing Activities
A22: Disposal of Fixed Assets | B22: ARD_DISPOSAL_OF_FIXED_ASSETS | C22: 2.5779 | D22: 0.3139 | E22: 0.2927 | F22: 3.3106 | G22: 8.4079
A23: Capital Expenditures | B23: ARD_CAPITAL_EXPENDITURES | C23: -68.835 | D23: -146.4331 | E23: -183.6785 | F23: -144.669 | G23: -129.0888
A24: Proceeds From Investments | B24: ARD_PROCEEDS_FROM_INVESTMENTS | C24: 83.9274 | D24: 40.9296 | E24: 76.2923 | F24: 58.91 | G24: 76.913
A25: Purchases of Investments | B25: ARD_PURCHASES_OF_INVESTMENTS | C25: -113.2042 | D25: -30.1074 | E25: -168.933 | F25: -78.7461 | G25: -48.7375
A26: Acquisition of Business | B26: ARD_ACQUISITION_OF_BUSINESS | C26: -12.0715 | D26: 0 | E26: -18.9365 | F26: -2.8708 | G26: -16.2133
A27: Other Investing Activities | B27: ARD_OTHER_INVESTING_ACTIVITIES | C27: -5.5014 | D27: -3.6112 | E27: -4.4534 | F27: -38.0132 | G27: -158.1809
A28: Purchase Of Associates/Joint Ventures | B28: ARD_PURCHASE_ASSOC_JOINT_VENTURE | C28: — | D28: -33.8303 | E28: — | F28: — | G28: —
A29: Total Cash Flows From Investing | B29: ARD_TOT_CASHFLOWS_FROM_INVESTING | C29: -113.107 | D29: -172.7385 | E29: -299.4163 | F29: -202.0784 | G29: -266.8995
A30: Cash from Financing Activities
A31: Dividends Paid | B31: ARD_DIVIDEND_PD | C31: -115.2856 | D31: -113.0919 | E31: -112.1501 | F31: -110.438 | G31: -106.8606
A32: Increase In Long-Term Borrowings | B32: ARD_INCR_IN_LT_BORROW | C32: 0 | D32: — | E32: — | F32: — | G32: —
A33: Decrease In Long-Term Borrowings | B33: ARD_DECR_IN_LT_BORROW | C33: 0 | D33: 0 | E33: — | F33: — | G33: —
A34: Issuance of Common Stock | B34: ARD_ISSUANCE_OF_COMMON_STOCK | C34: 29.8088 | D34: 16.6023 | E34: 29.3983 | F34: 27.2951 | G34: 14.4602
A35: Repurchase of Common Stock | B35: ARD_REPURCHASE_OF_COMMON_STOCK | C35: -324.6431 | D35: -112.5294 | E35: -147.4011 | F35: -206.1081 | G35: -315.4995
A36: Net Change In Cash | B36: ARD_NET_CHANGE_IN_CASH | C36: -161.0594 | D36: -43.557 | E36: 7.6804 | F36: 6.8837 | G36: -87.6731
A37: Cash and Cash Equivalents (End of Period) | B37: ARD_CASH_CASH_EQUIV_END_OF_PER | C37: 262.3117 | D37: 218.7546 | E37: 226.435 | F37: 233.3188 | G37: 145.6457
A38: Cash and Cash Equivalents (Beg of Period) | B38: ARD_CASH_CASH_EQUIV_BEG_OF_PER | C38: 423.371 | D38: 262.3117 | E38: 218.7546 | F38: 226.435 | G38: 233.3188
A39: Total Cash Flows From Financing | B39: ARD_TOT_CASHFLOWS_FROM_FINANCING | C39: -410.12 | D39: -209.0191 | E39: -230.1529 | F39: -289.2511 | G39: -407.8998
A40: Reference Items
A41: Cash Paid For Taxes | B41: ARDR_CASH_PAID_FOR_TAXES | C41: — | D41: — | E41: — | F41: — | G41: —
A42: Source: Bloomberg | C42: Right click to show data transparency (not supported for all values)

Sheet Bal Sheet - As Reported
A2: Gentex Corp (GNTX US) - As Reported
A4: In Millions of USD except Per Share | C4: FY 2021 | D4: FY 2022 | E4: FY 2023 | F4: FY 2024 | G4: FY 2025
A5: 12 Months Ending | C5: 12/31/2021 | D5: 12/31/2022 | E5: 12/31/2023 | F5: 12/31/2024 | G5: 12/31/2025
A6: Balance Sheet
A7: Current Assets
A8: Cash and Equivalents | B8: ARD_CASH_AND_EQUIVALENTS | C8: 262.3117 | D8: 214.7546 | E8: 226.435 | F8: 233.3188 | G8: 145.6457
A9: Accounts Receivable - Trade | B9: ARD_ACCTS_RECEIVABLE_TRADE | C9: 249.7949 | D9: 276.4938 | E9: 321.8099 | F9: 295.3444 | G9: 368.5176
A10: Inventories | B10: ARD_INVENTORY | C10: 316.2674 | D10: 404.3603 | E10: 402.473 | F10: 436.4974 | G10: 516.2536
A11: Prepaid Expenses and Other | B11: ARD_PREPAID_EXP_AND_OTHER | C11: — | D11: — | E11: — | F11: — | G11: —
A12: Restricted Cash (Short-Term) | B12: ARD_RESTRICTED_CASH_ST | C12: — | D12: 4 | E12: 0 | F12: — | G12: —
A13: Other Current Assets | B13: ARD_OTHER_CURRENT_ASSETS | C13: 39.1781 | D13: 26.0363 | E13: 32.6638 | F13: 49.8628 | G13: 92.631
A14: Short-Term Investments | B14: ARD_ST_INVEST | C14: 5.4236 | D14: 23.0074 | E14: 14.3565 | F14: 22.3048 | G14: 5.3866
A15: Total Current Assets | B15: ARD_TOTAL_CUR_ASSETS | C15: 872.9757 | D15: 948.6524 | E15: 997.7382 | F15: 1037.3282 | G15: 1128.4345
A16: Noncurrent Assets
A17: Long Term Investments | B17: ARD_LT_INVEST | C17: 207.6931 | D17: 153.906 | E17: 299.0809 | F17: 339.604 | G17: 272.9759
A18: Land and Buildings | B18: ARD_LAND_AND_BUILDINGS | C18: 363.6464 | D18: 376.9344 | E18: 472.1123 | F18: 531.2611 | G18: 591.488
A19: Construction In Progress | B19: ARD_CONSTRUCTION_IN_PROGRESS | C19: 77.5922 | D19: 165.5749 | E19: 158.3272 | F19: 177.9073 | G19: 83.0484
A20: Furniture/Machinery/Equipment | B20: ARD_FURNITURE_MACHINERY_EQUIP | C20: 883.2401 | D20: 935.8483 | E20: 1011.9307 | F20: 1065.1097 | G20: 1240.2128
A21: Property Plant & Equipment - Gross | B21: ARD_PROPERTY_PLANT_EQUIP_GROSS | C21: 1324.4786 | D21: 1478.3575 | E21: 1642.3703 | F21: 1774.2781 | G21: 1914.7492
A22: Accumulated Depreciation | B22: ARD_ACCUMULATED_DEPREC | C22: 860.357 | D22: 928.3245 | E22: 989.4926 | F22: 1045.7966 | G22: 1123.8138
A23: Property Plant & Equipment - Net | B23: ARD_PROPERTY_PLANT_EQUIP_NET | C23: 464.1217 | D23: 550.033 | E23: 652.8777 | F23: 728.4815 | G23: 790.9354
A24: Deferred Income Tax Asset (Long-Term) | B24: ARD_DEFERRED_INC_TAX_ASSET_LT | C24: — | D24: 25.5287 | E24: 41.1138 | F24: 53.1548 | G24: 108.3386
A25: Other Intangible Assets | B25: ARD_OTHER_INTANGIBLE_ASSET | C25: 272.6404 | D25: 286.8763 | E25: 280.5215 | F25: 195.1572 | G25: 189.3414
A26: Investment In Affiliates/Joint Ventures | B26: ARD_INVESTMENT_IN_AFFILIATE_JV | C26: — | D26: 48.426 | E26: — | F26: — | G26: —
A27: Goodwill | B27: ARD_GOODWLL | C27: 313.9602 | D27: 313.8075 | E27: 340.1056 | F27: 340.6689 | G27: 357.2119
A28: Patents/Trademarks/Copyrights | B28: ARD_PATENTS_TRADEMRK_COPYRIGHT | C28: — | D28: — | E28: — | F28: 66.4264 | G28: 81.3552
A29: Total Non-Current Assets | B29: ARD_TOTAL_NONCURRENT_ASSETS | C29: 1258.4154 | D29: 1378.5775 | E29: 1613.6994 | F29: — | G29: —
A30: Total Assets | B30: ARD_TOT_ASSETS | C30: 2131.3912 | D30: 2327.2299 | E30: 2611.4376 | F30: 2760.821 | G30: 2928.5928
A31: Current Liabilities
A32: Accounts Payable - Trade | B32: ARD_ACCOUNTS_PAYABLE_TRADE | C32: 98.3429 | D32: 151.74 | E32: 184.3988 | F32: 168.3149 | G32: 248.9835
A33: Current Portion of Long-Term Debt | B33: ARD_CURRENT_PORTION_OF_LT_DEBT | C33: — | D33: — | E33: — | F33: — | G33: —
A34: Accrued Compensation/Postretirement Obligation | B34: ARD_ACC_COMP_POSTRETIRE_OBLIG | C34: 14.0196 | D34: 17.5176 | E34: 22.7256 | F34: 19.5264 | G34: 23.1972
A35: Accrued Expenses | B35: ARD_ACCRUED_EXPENSES | C35: 19.1409 | D35: 19.2084 | E35: 20.8989 | F35: 21.0875 | G35: 29.3581
A36: Dividends Accrued/Payable | B36: ARD_DVD_ACCRUED_PAYABLE | C36: 28.3729 | D36: 28.1003 | E36: 27.7747 | F36: 27.2649 | G36: 25.8534
A37: Other Current Liabilities | B37: ARD_OTHER_CURRENT_LIABILITIES | C37: 21.5829 | D37: 15.2595 | E37: 15.1175 | F37: 16.0595 | G37: 59.3038
A38: Income Taxes Accrued/Payable | B38: ARD_INCOME_TAX_ACCRUED_PAYABLE | C38: 0.1969 | D38: 18.7269 | E38: 0.6934 | F38: 0.4395 | G38: 0.847
A39: Total Current Liabilities | B39: ARD_TOTAL_CURRENT_LIABILITIES | C39: 181.6561 | D39: 250.5528 | E39: 271.609 | F39: 252.6927 | G39: 387.543
A40: Non Current Liabilities
A41: Long Term Debt | B41: ARD_LT_DEBT | C41: — | D41: — | E41: — | F41: — | G41: —
A42: Deferred Income Taxes (Liabilities) | B42: ARD_DEFERRED_INCOME_TAXES_LIAB | C42: 0 | D42: — | E42: — | F42: — | G42: 0.9089
...
